2024-09-10 17:07:08,590 INFO    StreamThr :527504 [internal.py:wandb_internal():85] W&B internal server running at pid: 527504, started at: 2024-09-10 17:07:08.589819
2024-09-10 17:07:08,591 DEBUG   HandlerThread:527504 [handler.py:handle_request():158] handle_request: status
2024-09-10 17:07:08,593 INFO    WriterThread:527504 [datastore.py:open_for_write():87] open: /home/ubuntu/frontend/bistro/wandb/run-20240910_170708-Validator-5F4UU/run-Validator-5F4UU.wandb
2024-09-10 17:07:08,593 DEBUG   SenderThread:527504 [sender.py:send():391] send: header
2024-09-10 17:07:08,594 DEBUG   SenderThread:527504 [sender.py:send():391] send: run
2024-09-10 17:07:08,597 INFO    SenderThread:527504 [sender.py:_setup_resume():761] checking resume status for None/bistro/Validator-5F4UU
2024-09-10 17:07:08,745 ERROR   SenderThread:527504 [internal_api.py:execute():349] 409 response executing GraphQL.
2024-09-10 17:07:08,745 ERROR   SenderThread:527504 [internal_api.py:execute():350] {"errors":[{"message":"run Validator-5F4UU was previously created and deleted; try a new run name","path":["upsertBucket"]}],"data":{"upsertBucket":null}}
2024-09-10 17:07:09,854 ERROR   SenderThread:527504 [internal_api.py:execute():349] 409 response executing GraphQL.
2024-09-10 17:07:09,854 ERROR   SenderThread:527504 [internal_api.py:execute():350] {"errors":[{"message":"run Validator-5F4UU was previously created and deleted; try a new run name","path":["upsertBucket"]}],"data":{"upsertBucket":null}}
2024-09-10 17:07:12,095 ERROR   SenderThread:527504 [internal_api.py:execute():349] 409 response executing GraphQL.
2024-09-10 17:07:12,095 ERROR   SenderThread:527504 [internal_api.py:execute():350] {"errors":[{"message":"run Validator-5F4UU was previously created and deleted; try a new run name","path":["upsertBucket"]}],"data":{"upsertBucket":null}}
2024-09-10 17:07:12,096 INFO    SenderThread:527504 [retry.py:__call__():172] Retry attempt failed:
Traceback (most recent call last):
  File "/home/ubuntu/frontend/venv/lib/python3.10/site-packages/wandb/sdk/lib/retry.py", line 131, in __call__
    result = self._call_fn(*args, **kwargs)
  File "/home/ubuntu/frontend/venv/lib/python3.10/site-packages/wandb/sdk/internal/internal_api.py", line 345, in execute
    return self.client.execute(*args, **kwargs)  # type: ignore
  File "/home/ubuntu/frontend/venv/lib/python3.10/site-packages/wandb/vendor/gql-0.2.0/wandb_gql/client.py", line 52, in execute
    result = self._get_result(document, *args, **kwargs)
  File "/home/ubuntu/frontend/venv/lib/python3.10/site-packages/wandb/vendor/gql-0.2.0/wandb_gql/client.py", line 60, in _get_result
    return self.transport.execute(document, *args, **kwargs)
  File "/home/ubuntu/frontend/venv/lib/python3.10/site-packages/wandb/sdk/lib/gql_request.py", line 59, in execute
    request.raise_for_status()
  File "/home/ubuntu/frontend/venv/lib/python3.10/site-packages/requests/models.py", line 1024, in raise_for_status
    raise HTTPError(http_error_msg, response=self)
requests.exceptions.HTTPError: 409 Client Error: Conflict for url: https://api.wandb.ai/graphql
2024-09-10 17:07:13,595 DEBUG   HandlerThread:527504 [handler.py:handle_request():158] handle_request: keepalive
2024-09-10 17:07:16,781 ERROR   SenderThread:527504 [internal_api.py:execute():349] 409 response executing GraphQL.
2024-09-10 17:07:16,781 ERROR   SenderThread:527504 [internal_api.py:execute():350] {"errors":[{"message":"run Validator-5F4UU was previously created and deleted; try a new run name","path":["upsertBucket"]}],"data":{"upsertBucket":null}}
2024-09-10 17:07:18,597 DEBUG   HandlerThread:527504 [handler.py:handle_request():158] handle_request: keepalive
2024-09-10 17:07:23,598 DEBUG   HandlerThread:527504 [handler.py:handle_request():158] handle_request: keepalive
2024-09-10 17:07:24,951 ERROR   SenderThread:527504 [internal_api.py:execute():349] 409 response executing GraphQL.
2024-09-10 17:07:24,951 ERROR   SenderThread:527504 [internal_api.py:execute():350] {"errors":[{"message":"run Validator-5F4UU was previously created and deleted; try a new run name","path":["upsertBucket"]}],"data":{"upsertBucket":null}}
2024-09-10 17:07:28,600 DEBUG   HandlerThread:527504 [handler.py:handle_request():158] handle_request: keepalive
2024-09-10 17:07:33,601 DEBUG   HandlerThread:527504 [handler.py:handle_request():158] handle_request: keepalive
2024-09-10 17:07:38,603 DEBUG   HandlerThread:527504 [handler.py:handle_request():158] handle_request: keepalive
2024-09-10 17:07:43,604 DEBUG   HandlerThread:527504 [handler.py:handle_request():158] handle_request: keepalive
2024-09-10 17:07:43,728 ERROR   SenderThread:527504 [internal_api.py:execute():349] 409 response executing GraphQL.
2024-09-10 17:07:43,728 ERROR   SenderThread:527504 [internal_api.py:execute():350] {"errors":[{"message":"run Validator-5F4UU was previously created and deleted; try a new run name","path":["upsertBucket"]}],"data":{"upsertBucket":null}}
2024-09-10 17:07:48,606 DEBUG   HandlerThread:527504 [handler.py:handle_request():158] handle_request: keepalive
2024-09-10 17:07:53,607 DEBUG   HandlerThread:527504 [handler.py:handle_request():158] handle_request: keepalive
2024-09-10 17:07:58,609 DEBUG   HandlerThread:527504 [handler.py:handle_request():158] handle_request: keepalive
2024-09-10 17:08:03,610 DEBUG   HandlerThread:527504 [handler.py:handle_request():158] handle_request: keepalive
2024-09-10 17:08:08,612 DEBUG   HandlerThread:527504 [handler.py:handle_request():158] handle_request: keepalive
2024-09-10 17:08:13,613 DEBUG   HandlerThread:527504 [handler.py:handle_request():158] handle_request: keepalive
2024-09-10 17:08:18,615 DEBUG   HandlerThread:527504 [handler.py:handle_request():158] handle_request: keepalive
2024-09-10 17:08:22,028 ERROR   SenderThread:527504 [internal_api.py:execute():349] 409 response executing GraphQL.
2024-09-10 17:08:22,028 ERROR   SenderThread:527504 [internal_api.py:execute():350] {"errors":[{"message":"run Validator-5F4UU was previously created and deleted; try a new run name","path":["upsertBucket"]}],"data":{"upsertBucket":null}}
2024-09-10 17:08:23,616 DEBUG   HandlerThread:527504 [handler.py:handle_request():158] handle_request: keepalive
2024-09-10 17:08:28,618 DEBUG   HandlerThread:527504 [handler.py:handle_request():158] handle_request: keepalive
